Workbook

Sheet Dashboard
A1: Dashboard de Triagem Example Organization 2026 | AA1: Região (apoio heatmap) | AB1: Qtd
J2: Status dos candidatos | R2: Distribuição por turma | AA2: AC | AB2: =COUNTIFS(Candidatos!B2:B1001,"?*",Candidatos!F2:F1001,AA2)
A3: Indicador | B3: Valor | C3: Indicador | D3: Valor | E3: Indicador | F3: Valor | G3: Indicador | H3: Valor | J3: Categoria | K3: Qtd | L3: Barra | R3: Turma | S3: Qtd | T3: Barra | AA3: AL | AB3: =COUNTIFS(Candidatos!B2:B1001,"?*",Candidatos!F2:F1001,AA3)
A4: Total de inscritos | B4: =COUNTIF(Candidatos!B2:B1001,"?*") | C4: Sem equipe | D4: =COUNTIFS(Candidatos!B2:B1001,"?*",Candidatos!J2:J1001,"") | E4: Sem agendamento | F4: =COUNTIFS(Candidatos!B2:B1001,"?*",Candidatos!K2:K1001,"") | G4: Sem status | H4: =COUNTIFS(Candidatos!B2:B1001,"?*",Candidatos!L2:L1001,"") | J4: =A9 | K4: =B9 | L4: =REPT("█",ROUND(IF(MAX($B$9:$B$14)=0,0,$K4/MAX($B$9:$B$14)*20),0)) | R4: =G9 | S4: =H9 | T4: =REPT("█",ROUND(IF(MAX($H$9:$H$11)=0,0,$S4/MAX($H$9:$H$11)*20),0)) | AA4: AP | AB4: =COUNTIFS(Candidatos!B2:B1001,"?*",Candidatos!F2:F1001,AA4)
A5: Aprovados | B5: =COUNTIFS(Candidatos!B2:B1001,"?*",Candidatos!L2:L1001,"Aprovado") | C5: Pré-aprovados | D5: =COUNTIFS(Candidatos!B2:B1001,"?*",Candidatos!L2:L1001,"Pré-aprovado") | E5: Em análise | F5: =COUNTIFS(Candidatos!B2:B1001,"?*",Candidatos!L2:L1001,"Em análise") | G5: Negados | H5: =COUNTIFS(Candidatos!B2:B1001,"?*",Candidatos!L2:L1001,"Negado") | J5: =A10 | K5: =B10 | L5: =REPT("█",ROUND(IF(MAX($B$9:$B$14)=0,0,$K5/MAX($B$9:$B$14)*20),0)) | R5: =G10 | S5: =H10 | T5: =REPT("█",ROUND(IF(MAX($H$9:$H$11)=0,0,$S5/MAX($H$9:$H$11)*20),0)) | AA5: AM | AB5: =COUNTIFS(Candidatos!B2:B1001,"?*",Candidatos!F2:F1001,AA5)
A6: Desistências | B6: =COUNTIFS(Candidatos!B2:B1001,"?*",Candidatos!L2:L1001,"Desistência") | C6: Taxa de aprovação | D6: =IFERROR(B5/B4,0) | E6: Pendências | F6: =COUNTIF(Candidatos!O2:O1001,"?*") | G6: Último ID | H6: =IFERROR(MAX(Candidatos!A2:A1001),0) | J6: =A11 | K6: =B11 | L6: =REPT("█",ROUND(IF(MAX($B$9:$B$14)=0,0,$K6/MAX($B$9:$B$14)*20),0)) | R6: =G11 | S6: =H11 | T6: =REPT("█",ROUND(IF(MAX($H$9:$H$11)=0,0,$S6/MAX($H$9:$H$11)*20),0)) | AA6: BA | AB6: =COUNTIFS(Candidatos!B2:B1001,"?*",Candidatos!F2:F1001,AA6)
J7: =A12 | K7: =B12 | L7: =REPT("█",ROUND(IF(MAX($B$9:$B$14)=0,0,$K7/MAX($B$9:$B$14)*20),0)) | AA7: CE | AB7: =COUNTIFS(Candidatos!B2:B1001,"?*",Candidatos!F2:F1001,AA7)
A8: Resumo por status | B8: Quantidade | D8: Resumo por equipe | E8: Quantidade | G8: Resumo por turma | H8: Quantidade | J8: =A13 | K8: =B13 | L8: =REPT("█",ROUND(IF(MAX($B$9:$B$14)=0,0,$K8/MAX($B$9:$B$14)*20),0)) | AA8: DF | AB8: =COUNTIFS(Candidatos!B2:B1001,"?*",Candidatos!F2:F1001,AA8)
A9: Aprovado | B9: =COUNTIFS(Candidatos!B2:B1001,"?*",Candidatos!L2:L1001,"Aprovado") | D9: Team A | E9: =COUNTIFS(Candidatos!B2:B1001,"?*",Candidatos!J2:J1001,"Team A") | G9: Online T | H9: =COUNTIFS(Candidatos!B2:B1001,"?*",Candidatos!G2:G1001,"Online T") | J9: =A14 | K9: =B14 | L9: =REPT("█",ROUND(IF(MAX($B$9:$B$14)=0,0,$K9/MAX($B$9:$B$14)*20),0)) | AA9: ES | AB9: =COUNTIFS(Candidatos!B2:B1001,"?*",Candidatos!F2:F1001,AA9)
A10: Pré-aprovado | B10: =COUNTIFS(Candidatos!B2:B1001,"?*",Candidatos!L2:L1001,"Pré-aprovado") | D10: Team B | E10: =COUNTIFS(Candidatos!B2:B1001,"?*",Candidatos!J2:J1001,"Team B") | G10: Online M | H10: =COUNTIFS(Candidatos!B2:B1001,"?*",Candidatos!G2:G1001,"Online M") | AA10: GO | AB10: =COUNTIFS(Candidatos!B2:B1001,"?*",Candidatos!F2:F1001,AA10)
A11: Em análise | B11: =COUNTIFS(Candidatos!B2:B1001,"?*",Candidatos!L2:L1001,"Em análise") | D11: Team C | E11: =COUNTIFS(Candidatos!B2:B1001,"?*",Candidatos!J2:J1001,"Team C") | G11: Presencial | H11: =COUNTIFS(Candidatos!B2:B1001,"?*",Candidatos!G2:G1001,"Presencial") | AA11: MA | AB11: =COUNTIFS(Candidatos!B2:B1001,"?*",Candidatos!F2:F1001,AA11)
A12: Negado | B12: =COUNTIFS(Candidatos!B2:B1001,"?*",Candidatos!L2:L1001,"Negado") | AA12: MT | AB12: =COUNTIFS(Candidatos!B2:B1001,"?*",Candidatos!F2:F1001,AA12)
A13: Desistência | B13: =COUNTIFS(Candidatos!B2:B1001,"?*",Candidatos!L2:L1001,"Desistência") | AA13: MS | AB13: =COUNTIFS(Candidatos!B2:B1001,"?*",Candidatos!F2:F1001,AA13)
A14: Sem status | B14: =COUNTIFS(Candidatos!B2:B1001,"?*",Candidatos!L2:L1001,"") | AA14: MG | AB14: =COUNTIFS(Candidatos!B2:B1001,"?*",Candidatos!F2:F1001,AA14)
AA15: PA | AB15: =COUNTIFS(Candidatos!B2:B1001,"?*",Candidatos!F2:F1001,AA15)
A16: Região | B16: Quantidade | D16: Instruções rápidas | AA16: PB | AB16: =COUNTIFS(Candidatos!B2:B1001,"?*",Candidatos!F2:F1001,AA16)
A17: SP | B17: =COUNTIFS(Candidatos!B2:B1001,"?*",Candidatos!F2:F1001,"SP") | D17: 1. Preencha a aba Database com os inscritos. | AA17: PR | AB17: =COUNTIFS(Candidatos!B2:B1001,"?*",Candidatos!F2:F1001,AA17)
A18: RJ | B18: =COUNTIFS(Candidatos!B2:B1001,"?*",Candidatos!F2:F1001,"RJ") | D18: 2. Faça a triagem na aba Candidatos. | AA18: PE | AB18: =COUNTIFS(Candidatos!B2:B1001,"?*",Candidatos!F2:F1001,AA18)
A19: BA | B19: =COUNTIFS(Candidatos!B2:B1001,"?*",Candidatos!F2:F1001,"BA") | D19: 3. As abas por status e equipe atualizam automaticamente. | AA19: PI | AB19: =COUNTIFS(Candidatos!B2:B1001,"?*",Candidatos!F2:F1001,AA19)
A20: MG | B20: =COUNTIFS(Candidatos!B2:B1001,"?*",Candidatos!F2:F1001,"MG") | D20: 4. Adicione novos motivos na aba legenda quando necessário. | J20: Distribuição por equipe | R20: Regiões monitoradas | AA20: RJ | AB20: =COUNTIFS(Candidatos!B2:B1001,"?*",Candidatos!F2:F1001,AA20)
A21: PE | B21: =COUNTIFS(Candidatos!B2:B1001,"?*",Candidatos!F2:F1001,"PE") | D21: 5. Esta versão foi preparada para Excel e Google Sheets. | J21: Equipe | K21: Qtd | L21: Barra | R21: Região | S21: Qtd | T21: Barra | AA21: RN | AB21: =COUNTIFS(Candidatos!B2:B1001,"?*",Candidatos!F2:F1001,AA21)
A22: PR | B22: =COUNTIFS(Candidatos!B2:B1001,"?*",Candidatos!F2:F1001,"PR") | J22: =D9 | K22: =E9 | L22: =REPT("█",ROUND(IF(MAX($E$9:$E$13)=0,0,$K22/MAX($E$9:$E$13)*20),0)) | R22: =A17 | S22: =B17 | T22: =REPT("█",ROUND(IF(MAX($B$17:$B$25)=0,0,$S22/MAX($B$17:$B$25)*20),0)) | AA22: RS | AB22: =COUNTIFS(Candidatos!B2:B1001,"?*",Candidatos!F2:F1001,AA22)
A23: RS | B23: =COUNTIFS(Candidatos!B2:B1001,"?*",Candidatos!F2:F1001,"RS") | D23: Observação | E23: Os dados são limitados às linhas 2:1001 para manter compatibilidade. | J23: =D10 | K23: =E10 | L23: =REPT("█",ROUND(IF(MAX($E$9:$E$13)=0,0,$K23/MAX($E$9:$E$13)*20),0)) | R23: =A18 | S23: =B18 | T23: =REPT("█",ROUND(IF(MAX($B$17:$B$25)=0,0,$S23/MAX($B$17:$B$25)*20),0)) | AA23: RO | AB23: =COUNTIFS(Candidatos!B2:B1001,"?*",Candidatos!F2:F1001,AA23)
A24: SC | B24: =COUNTIFS(Candidatos!B2:B1001,"?*",Candidatos!F2:F1001,"SC") | D24: Personalização | E24: Você pode pedir novos indicadores específicos depois. | J24: =D11 | K24: =E11 | L24: =REPT("█",ROUND(IF(MAX($E$9:$E$13)=0,0,$K24/MAX($E$9:$E$13)*20),0)) | R24: =A19 | S24: =B19 | T24: =REPT("█",ROUND(IF(MAX($B$17:$B$25)=0,0,$S24/MAX($B$17:$B$25)*20),0)) | AA24: RR | AB24: =COUNTIFS(Candidatos!B2:B1001,"?*",Candidatos!F2:F1001,AA24)
A25: Outras | B25: =COUNTIFS(Candidatos!F2:F1001,"?*",Candidatos!F2:F1001,"<>SP",Candidatos!F2:F1001,"<>RJ",Candidatos!F2:F1001,"<>BA",Candidatos!F2:F1001,"<>MG",Candidatos!F2:F1001,"<>PE",Candidatos!F2:F1001,"<>PR",Candidatos!F2:F1001,"<>RS",Candidatos!F2:F1001,"<>SC") | J25: =D12 | K25: =E12 | L25: =REPT("█",ROUND(IF(MAX($E$9:$E$13)=0,0,$K25/MAX($E$9:$E$13)*20),0)) | R25: =A20 | S25: =B20 | T25: =REPT("█",ROUND(IF(MAX($B$17:$B$25)=0,0,$S25/MAX($B$17:$B$25)*20),0)) | AA25: SC | AB25: =COUNTIFS(Candidatos!B2:B1001,"?*",Candidatos!F2:F1001,AA25)
J26: =D13 | K26: =E13 | L26: =REPT("█",ROUND(IF(MAX($E$9:$E$13)=0,0,$K26/MAX($E$9:$E$13)*20),0)) | R26: =A21 | S26: =B21 | T26: =REPT("█",ROUND(IF(MAX($B$17:$B$25)=0,0,$S26/MAX($B$17:$B$25)*20),0)) | AA26: SP | AB26: =COUNTIFS(Candidatos!B2:B1001,"?*",Candidatos!F2:F1001,AA26)
R27: =A22 | S27: =B22 | T27: =REPT("█",ROUND(IF(MAX($B$17:$B$25)=0,0,$S27/MAX($B$17:$B$25)*20),0)) | AA27: SE | AB27: =COUNTIFS(Candidatos!B2:B1001,"?*",Candidatos!F2:F1001,AA27)
R28: =A23 | S28: =B23 | T28: =REPT("█",ROUND(IF(MAX($B$17:$B$25)=0,0,$S28/MAX($B$17:$B$25)*20),0)) | AA28: TO | AB28: =COUNTIFS(Candidatos!B2:B1001,"?*",Candidatos!F2:F1001,AA28)
R29: =A24 | S29: =B24 | T29: =REPT("█",ROUND(IF(MAX($B$17:$B$25)=0,0,$S29/MAX($B$17:$B$25)*20),0)) | AA29: AD | AB29: =COUNTIFS(Candidatos!B2:B1001,"?*",Candidatos!F2:F1001,AA29)
R30: =A25 | S30: =B25 | T30: =REPT("█",ROUND(IF(MAX($B$17:$B$25)=0,0,$S30/MAX($B$17:$B$25)*20),0)) | AA30: AE | AB30: =COUNTIFS(Candidatos!B2:B1001,"?*",Candidatos!F2:F1001,AA30)
AA31: AF | AB31: =COUNTIFS(Candidatos!B2:B1001,"?*",Candidatos!F2:F1001,AA31)
AA32: AG | AB32: =COUNTIFS(Candidatos!B2:B1001,"?*",Candidatos!F2:F1001,AA32)
AA33: AI | AB33: =COUNTIFS(Candidatos!B2:B1001,"?*",Candidatos!F2:F1001,AA33)
AA34: AO | AB34: =COUNTIFS(Candidatos!B2:B1001,"?*",Candidatos!F2:F1001,AA34)
AA35: AQ | AB35: =COUNTIFS(Candidatos!B2:B1001,"?*",Candidatos!F2:F1001,AA35)
AA36: AR | AB36: =COUNTIFS(Candidatos!B2:B1001,"?*",Candidatos!F2:F1001,AA36)
AA37: AS | AB37: =COUNTIFS(Candidatos!B2:B1001,"?*",Candidatos!F2:F1001,AA37)
J38: Zona de calor por região (país/mundo) | AA38: AT | AB38: =COUNTIFS(Candidatos!B2:B1001,"?*",Candidatos!F2:F1001,AA38)
J39: AC | K39: AL | L39: AP | M39: AM | N39: BA | O39: CE | P39: DF | Q39: ES | R39: GO | S39: MA | T39: MT | U39: MS | V39: MG | W39: PA | X39: PB | Y39: PR | AA39: AU | AB39: =COUNTIFS(Candidatos!B2:B1001,"?*",Candidatos!F2:F1001,AA39)
J40: =COUNTIFS(Candidatos!B2:B1001,"?*",Candidatos!F2:F1001,J39) | K40: =COUNTIFS(Candidatos!B2:B1001,"?*",Candidatos!F2:F1001,K39) | L40: =COUNTIFS(Candidatos!B2:B1001,"?*",Candidatos!F2:F1001,L39) | M40: =COUNTIFS(Candidatos!B2:B1001,"?*",Candidatos!F2:F1001,M39) | N40: =COUNTIFS(Candidatos!B2:B1001,"?*",Candidatos!F2:F1001,N39) | O40: =COUNTIFS(Candidatos!B2:B1001,"?*",Candidatos!F2:F1001,O39) | P40: =COUNTIFS(Candidatos!B2:B1001,"?*",Candidatos!F2:F1001,P39) | Q40: =COUNTIFS(Candidatos!B2:B1001,"?*",Candidatos!F2:F1001,Q39) | R40: =COUNTIFS(Candidatos!B2:B1001,"?*",Candidatos!F2:F1001,R39) | S40: =COUNTIFS(Candidatos!B2:B1001,"?*",Candidatos!F2:F1001,S39) | T40: =COUNTIFS(Candidatos!B2:B1001,"?*",Candidatos!F2:F1001,T39) | U40: =COUNTIFS(Candidatos!B2:B1001,"?*",Candidatos!F2:F1001,U39) | V40: =COUNTIFS(Candidatos!B2:B1001,"?*",Candidatos!F2:F1001,V39) | W40: =COUNTIFS(Candidatos!B2:B1001,"?*",Candidatos!F2:F1001,W39) | X40: =COUNTIFS(Candidatos!B2:B1001,"?*",Candidatos!F2:F1001,X39) | Y40: =COUNTIFS(Candidatos!B2:B1001,"?*",Candidatos!F2:F1001,Y39) | AA40: AW | AB40: =COUNTIFS(Candidatos!B2:B1001,"?*",Candidatos!F2:F1001,AA40)
...

Sheet Candidatos
A1: ID | B1: Nome do inscrito(a) | C1: Data de inscrição | D1: E-mail | E1: Contato | F1: Região | G1: Turma | H1: Idade | I1: Renda Familiar | J1: Equipe Example Organization | K1: Agendamento | L1: Status | M1: Motivo | N1: Comentários | O1: Pendências | Q1: Orientação | R1: Descrição
A2: =IF(Database!B2="","",ROW()-1) | B2: =IF(Database!B2="","",Database!B2) | C2: =IF(Database!B2="","",Database!A2) | D2: =IF(Database!B2="","",Database!D2) | E2: =IF(Database!B2="","",Database!E2) | F2: =IF(Database!B2="","",Database!F2) | G2: =IF(Database!B2="","",Database!G2) | H2: =IF(Database!B2="","",Database!C2) | I2: =IF(Database!B2="","",Database!H2) | Q2: Preenchimento | R2: Edite apenas a Equipe Example Organization na coluna J. A triagem é feita nas abas individuais.
A3: =IF(Database!B3="","",ROW()-1) | B3: =IF(Database!B3="","",Database!B3) | C3: =IF(Database!B3="","",Database!A3) | D3: =IF(Database!B3="","",Database!D3) | E3: =IF(Database!B3="","",Database!E3) | F3: =IF(Database!B3="","",Database!F3) | G3: =IF(Database!B3="","",Database!G3) | H3: =IF(Database!B3="","",Database!C3) | I3: =IF(Database!B3="","",Database!H3) | Q3: Equipe | R3: Ao escolher uma equipe, o candidato aparece na aba da pessoa.
A4: =IF(Database!B4="","",ROW()-1) | B4: =IF(Database!B4="","",Database!B4) | C4: =IF(Database!B4="","",Database!A4) | D4: =IF(Database!B4="","",Database!D4) | E4: =IF(Database!B4="","",Database!E4) | F4: =IF(Database!B4="","",Database!F4) | G4: =IF(Database!B4="","",Database!G4) | H4: =IF(Database!B4="","",Database!C4) | I4: =IF(Database!B4="","",Database!H4) | Q4: Triagem | R4: Agendamento, Status, Motivo e Comentários feitos pela equipe retornam automaticamente.
A5: =IF(Database!B5="","",ROW()-1) | B5: =IF(Database!B5="","",Database!B5) | C5: =IF(Database!B5="","",Database!A5) | D5: =IF(Database!B5="","",Database!D5) | E5: =IF(Database!B5="","",Database!E5) | F5: =IF(Database!B5="","",Database!F5) | G5: =IF(Database!B5="","",Database!G5) | H5: =IF(Database!B5="","",Database!C5) | I5: =IF(Database!B5="","",Database!H5) | Q5: Pendências | R5: A coluna O indica se faltou equipe, agendamento ou status.
A6: =IF(Database!B6="","",ROW()-1) | B6: =IF(Database!B6="","",Database!B6) | C6: =IF(Database!B6="","",Database!A6) | D6: =IF(Database!B6="","",Database!D6) | E6: =IF(Database!B6="","",Database!E6) | F6: =IF(Database!B6="","",Database!F6) | G6: =IF(Database!B6="","",Database!G6) | H6: =IF(Database!B6="","",Database!C6) | I6: =IF(Database!B6="","",Database!H6)
A7: =IF(Database!B7="","",ROW()-1) | B7: =IF(Database!B7="","",Database!B7) | C7: =IF(Database!B7="","",Database!A7) | D7: =IF(Database!B7="","",Database!D7) | E7: =IF(Database!B7="","",Database!E7) | F7: =IF(Database!B7="","",Database!F7) | G7: =IF(Database!B7="","",Database!G7) | H7: =IF(Database!B7="","",Database!C7) | I7: =IF(Database!B7="","",Database!H7)
A8: =IF(Database!B8="","",ROW()-1) | B8: =IF(Database!B8="","",Database!B8) | C8: =IF(Database!B8="","",Database!A8) | D8: =IF(Database!B8="","",Database!D8) | E8: =IF(Database!B8="","",Database!E8) | F8: =IF(Database!B8="","",Database!F8) | G8: =IF(Database!B8="","",Database!G8) | H8: =IF(Database!B8="","",Database!C8) | I8: =IF(Database!B8="","",Database!H8)
A9: =IF(Database!B9="","",ROW()-1) | B9: =IF(Database!B9="","",Database!B9) | C9: =IF(Database!B9="","",Database!A9) | D9: =IF(Database!B9="","",Database!D9) | E9: =IF(Database!B9="","",Database!E9) | F9: =IF(Database!B9="","",Database!F9) | G9: =IF(Database!B9="","",Database!G9) | H9: =IF(Database!B9="","",Database!C9) | I9: =IF(Database!B9="","",Database!H9)
A10: =IF(Database!B10="","",ROW()-1) | B10: =IF(Database!B10="","",Database!B10) | C10: =IF(Database!B10="","",Database!A10) | D10: =IF(Database!B10="","",Database!D10) | E10: =IF(Database!B10="","",Database!E10) | F10: =IF(Database!B10="","",Database!F10) | G10: =IF(Database!B10="","",Database!G10) | H10: =IF(Database!B10="","",Database!C10) | I10: =IF(Database!B10="","",Database!H10)
A11: =IF(Database!B11="","",ROW()-1) | B11: =IF(Database!B11="","",Database!B11) | C11: =IF(Database!B11="","",Database!A11) | D11: =IF(Database!B11="","",Database!D11) | E11: =IF(Database!B11="","",Database!E11) | F11: =IF(Database!B11="","",Database!F11) | G11: =IF(Database!B11="","",Database!G11) | H11: =IF(Database!B11="","",Database!C11) | I11: =IF(Database!B11="","",Database!H11)
A12: =IF(Database!B12="","",ROW()-1) | B12: =IF(Database!B12="","",Database!B12) | C12: =IF(Database!B12="","",Database!A12) | D12: =IF(Database!B12="","",Database!D12) | E12: =IF(Database!B12="","",Database!E12) | F12: =IF(Database!B12="","",Database!F12) | G12: =IF(Database!B12="","",Database!G12) | H12: =IF(Database!B12="","",Database!C12) | I12: =IF(Database!B12="","",Database!H12)
A13: =IF(Database!B13="","",ROW()-1) | B13: =IF(Database!B13="","",Database!B13) | C13: =IF(Database!B13="","",Database!A13) | D13: =IF(Database!B13="","",Database!D13) | E13: =IF(Database!B13="","",Database!E13) | F13: =IF(Database!B13="","",Database!F13) | G13: =IF(Database!B13="","",Database!G13) | H13: =IF(Database!B13="","",Database!C13) | I13: =IF(Database!B13="","",Database!H13)
A14: =IF(Database!B14="","",ROW()-1) | B14: =IF(Database!B14="","",Database!B14) | C14: =IF(Database!B14="","",Database!A14) | D14: =IF(Database!B14="","",Database!D14) | E14: =IF(Database!B14="","",Database!E14) | F14: =IF(Database!B14="","",Database!F14) | G14: =IF(Database!B14="","",Database!G14) | H14: =IF(Database!B14="","",Database!C14) | I14: =IF(Database!B14="","",Database!H14)
A15: =IF(Database!B15="","",ROW()-1) | B15: =IF(Database!B15="","",Database!B15) | C15: =IF(Database!B15="","",Database!A15) | D15: =IF(Database!B15="","",Database!D15) | E15: =IF(Database!B15="","",Database!E15) | F15: =IF(Database!B15="","",Database!F15) | G15: =IF(Database!B15="","",Database!G15) | H15: =IF(Database!B15="","",Database!C15) | I15: =IF(Database!B15="","",Database!H15)
A16: =IF(Database!B16="","",ROW()-1) | B16: =IF(Database!B16="","",Database!B16) | C16: =IF(Database!B16="","",Database!A16) | D16: =IF(Database!B16="","",Database!D16) | E16: =IF(Database!B16="","",Database!E16) | F16: =IF(Database!B16="","",Database!F16) | G16: =IF(Database!B16="","",Database!G16) | H16: =IF(Database!B16="","",Database!C16) | I16: =IF(Database!B16="","",Database!H16)
A17: =IF(Database!B17="","",ROW()-1) | B17: =IF(Database!B17="","",Database!B17) | C17: =IF(Database!B17="","",Database!A17) | D17: =IF(Database!B17="","",Database!D17) | E17: =IF(Database!B17="","",Database!E17) | F17: =IF(Database!B17="","",Database!F17) | G17: =IF(Database!B17="","",Database!G17) | H17: =IF(Database!B17="","",Database!C17) | I17: =IF(Database!B17="","",Database!H17)
... A1001: =IF(Database!B1001="","",ROW()-1) | B1001: =IF(Database!B1001="","",Database!B1001) | C1001: =IF(Database!B1001="","",Database!A1001) | D1001: =IF(Database!B1001="","",Database!D1001) | E1001: =IF(Database!B1001="","",Database!E1001) | F1001: =IF(Database!B1001="","",Database!F1001) | G1001: =IF(Database!B1001="","",Database!G1001) | H1001: =IF(Database!B1001="","",Database!C1001) | I1001: =IF(Database!B1001="","",Database!H1001)

Sheet Aprovados
A1: ID | B1: Nome do inscrito(a) | C1: Data de inscrição | D1: E-mail | E1: Contato | F1: Região | G1: Turma | H1: Idade | I1: Renda Familiar | J1: Equipe Example Organization | K1: Agendamento | L1: Status | M1: Motivo | N1: Comentários | O1: Pendências | Q1: Status filtrado | R1: Observação
A2: =IFERROR(FILTER(Candidatos!A2:O1001,Candidatos!L2:L1001="Aprovado"),"") | Q2: Aprovado | R2: Atualiza automaticamente com base na aba Candidatos.
Q3: Total | R3: =COUNTIFS(Candidatos!B2:B1001,"?*",Candidatos!L2:L1001,"Aprovado")

Sheet Em análise
A1: ID | B1: Nome do inscrito(a) | C1: Data de inscrição | D1: E-mail | E1: Contato | F1: Região | G1: Turma | H1: Idade | I1: Renda Familiar | J1: Equipe Example Organization | K1: Agendamento | L1: Status | M1: Motivo | N1: Comentários | O1: Pendências | Q1: Status filtrado | R1: Observação
A2: =IFERROR(FILTER(Candidatos!A2:O1001,Candidatos!L2:L1001="Em análise"),"") | Q2: Em análise | R2: Atualiza automaticamente com base na aba Candidatos.
Q3: Total | R3: =COUNTIFS(Candidatos!B2:B1001,"?*",Candidatos!L2:L1001,"Em análise")

Sheet Negado
A1: ID | B1: Nome do inscrito(a) | C1: Data de inscrição | D1: E-mail | E1: Contato | F1: Região | G1: Turma | H1: Idade | I1: Renda Familiar | J1: Equipe Example Organization | K1: Agendamento | L1: Status | M1: Motivo | N1: Comentários | O1: Pendências | Q1: Status filtrado | R1: Observação
A2: =IFERROR(FILTER(Candidatos!A2:O1001,Candidatos!L2:L1001="Negado"),"") | Q2: Negado | R2: Atualiza automaticamente com base na aba Candidatos.
Q3: Total | R3: =COUNTIFS(Candidatos!B2:B1001,"?*",Candidatos!L2:L1001,"Negado")

Sheet Pré-aprovado
A1: ID | B1: Nome do inscrito(a) | C1: Data de inscrição | D1: E-mail | E1: Contato | F1: Região | G1: Turma | H1: Idade | I1: Renda Familiar | J1: Equipe Example Organization | K1: Agendamento | L1: Status | M1: Motivo | N1: Comentários | O1: Pendências | Q1: Status filtrado | R1: Observação
A2: =IFERROR(FILTER(Candidatos!A2:O1001,Candidatos!L2:L1001="Pré-aprovado"),"") | Q2: Pré-aprovado | R2: Atualiza automaticamente com base na aba Candidatos.
Q3: Total | R3: =COUNTIFS(Candidatos!B2:B1001,"?*",Candidatos!L2:L1001,"Pré-aprovado")

Sheet Desistência
A1: ID | B1: Nome do inscrito(a) | C1: Data de inscrição | D1: E-mail | E1: Contato | F1: Região | G1: Turma | H1: Idade | I1: Renda Familiar | J1: Equipe Example Organization | K1: Agendamento | L1: Status | M1: Motivo | N1: Comentários | O1: Pendências | Q1: Status filtrado | R1: Observação
A2: =IFERROR(FILTER(Candidatos!A2:O1001,Candidatos!L2:L1001="Desistência"),"") | Q2: Desistência | R2: Atualiza automaticamente com base na aba Candidatos.
Q3: Total | R3: =COUNTIFS(Candidatos!B2:B1001,"?*",Candidatos!L2:L1001,"Desistência")

Sheet Database
A1: Data de inscrição | B1: Nome do inscrito(a) | C1: Idade | D1: E-mail | E1: Celular/WhatsApp | F1: Região | G1: Turma | H1: Renda Familiar | J1: Orientação | K1: Descrição
A2: 46029 | B2: Person 001 | C2: 19 | D2: person001@example.invalid | E2: +55 00 90000-0001 | F2: SP | G2: Online Morning | H2: Up to 1 minimum wage | J2: Preenchimento | K2: Preencha apenas as colunas A:H nesta aba.
A3: 46031 | B3: Person 002 | C3: 22 | D3: person002@example.invalid | E3: +55 00 90000-0002 | F3: RJ | G3: Online Evening | H3: 1 to 2 minimum wages | J3: Padronização | K3: Região, turma e renda possuem listas suspensas.
A4: 46033 | B4: Person 003 | C4: 25 | D4: person003@example.invalid | E4: +55 00 90000-0003 | F4: MG | G4: In Person | H4: 2 to 3 minimum wages | J4: Fluxo | K4: A aba Candidatos puxará os dados automaticamente.
A5: 46035 | B5: Person 004 | C5: 28 | D5: person004@example.invalid | E5: +55 00 90000-0004 | F5: BA | G5: Online Morning | H5: Above 3 minimum wages
A6: 46037 | B6: Person 005 | C6: 31 | D6: person005@example.invalid | E6: +55 00 90000-0005 | F6: PR | G6: Online Evening | H6: Not provided
A7: 46039 | B7: Person 006 | C7: 34 | D7: person006@example.invalid | E7: +55 00 90000-0006 | F7: PE | G7: In Person | H7: Up to 1 minimum wage
A8: 46041 | B8: Person 007 | C8: 37 | D8: person007@example.invalid | E8: +55 00 90000-0007 | F8: SP | G8: Online Morning | H8: 1 to 2 minimum wages
A9: 46043 | B9: Person 008 | C9: 40 | D9: person008@example.invalid | E9: +55 00 90000-0008 | F9: RJ | G9: Online Evening | H9: 2 to 3 minimum wages
A10: 46045 | B10: Person 009 | C10: 43 | D10: person009@example.invalid | E10: +55 00 90000-0009 | F10: MG | G10: In Person | H10: Above 3 minimum wages
A11: 46047 | B11: Person 010 | C11: 46 | D11: person010@example.invalid | E11: +55 00 90000-0010 | F11: BA | G11: Online Morning | H11: Not provided
A12: 46049 | B12: Person 011 | C12: 49 | D12: person011@example.invalid | E12: +55 00 90000-0011 | F12: PR | G12: Online Evening | H12: Up to 1 minimum wage
A13: 46051 | B13: Person 012 | C13: 52 | D13: person012@example.invalid | E13: +55 00 90000-0012 | F13: PE | G13: In Person | H13: 1 to 2 minimum wages
A14: 46053 | B14: Person 013 | C14: 16 | D14: person013@example.invalid | E14: +55 00 90000-0013 | F14: SP | G14: Online Morning | H14: 2 to 3 minimum wages
A15: 46055 | B15: Person 014 | C15: 19 | D15: person014@example.invalid | E15: +55 00 90000-0014 | F15: RJ | G15: Online Evening | H15: Above 3 minimum wages
A16: 46057 | B16: Person 015 | C16: 22 | D16: person015@example.invalid | E16: +55 00 90000-0015 | F16: MG | G16: In Person | H16: Not provided
... A37: 46099 | B37: Person 036 | C37: 46 | D37: person036@example.invalid | E37: +55 00 90000-0036 | F37: PE | G37: In Person | H37: Up to 1 minimum wage

Sheet legenda
A1: Região | B1: Status | C1: Equipe Example Organization | D1: Turma | E1: Faixa etária | F1: Motivo | G1: Renda Familiar | I1: Observações | J1: Descrição
A2: AC | B2: Pré-aprovado | C2: Team A | D2: Online T | E2: Menos de 16 anos | F2: Sem interesse | G2: Até 1 salário mínimo | I2: Região | J2: Use a sigla do estado brasileiro ou a sigla ISO-2 do país.
A3: AL | B3: Em análise | C3: Team B | D3: Online M | E3: Entre 16 a 24 anos | F3: desistencia | G3: De 1 a 2 salários mínimos | I3: Motivo | J3: Lista de opções usada no campo Motivo das abas da equipe.
A4: AP | B4: Negado | C4: Team C | D4: Presencial | E4: Mais de 24 anos | F4: conflito de agenda | G4: De 2 a 3 salários mínimos | I4: Equipe | J4: As abas individuais puxam automaticamente os candidatos atribuídos.
A5: AM | B5: Desistência | F5: trabalho | G5: Acima de 3 salários mínimos | I5: Status | J5: Valores usados no dashboard e nas abas automáticas.
A6: BA | B6: Aprovado | F6: inscrição incorreta | G6: Não informado | I6: Turma | J6: Mantidas conforme a planilha original.
A7: CE | F7: sem requisitos
A8: DF | F8: reserva
A9: ES | F9: sem retorno
A10: GO | F10: bloqueio
A11: MA | F11: sem retorno email
A12: MT | F12: sem acesso zap
A13: MS
A14: MG
A15: PA
A16: PB
A17: PR
A18: PE
A19: PI
A20: RJ
A21: RN
A22: RS
A23: RO
A24: RR
... A278: ZW

Sheet Team A
A1: ID | B1: Nome do inscrito(a) | C1: Data de inscrição | D1: E-mail | E1: Contato | F1: Região | G1: Turma | H1: Idade | I1: Renda Familiar | J1: Equipe Example Organization | K1: Agendamento | L1: Status | M1: Motivo | N1: Comentários | O1: Pendências | Q1: Equipe | R1: Observação
A2: =IFERROR(FILTER(Candidatos!A2:J1001,Candidatos!J2:J1001="Team A"),"") | O2: {=BYROW(HSTACK(B2:B1001,J2:L1001),LAMBDA(r,IF(INDEX(r,1,1)="","",TEXTJOIN(" | ",TRUE,IF(INDEX(r,1,2)="","Sem equipe",""),IF(INDEX(r,1,3)="","Sem agendamento",""),IF(INDEX(r,1,4)="","Sem status","")))))} | Q2: Team A | R2: Dados cadastrais automáticos. Edite Agendamento, Status, Motivo e Comentários nas colunas K:N.
Q3: Total | R3: =COUNTIFS(Candidatos!B2:B1001,"?*",Candidatos!J2:J1001,"Team A")

Sheet Team B
A1: ID | B1: Nome do inscrito(a) | C1: Data de inscrição | D1: E-mail | E1: Contato | F1: Região | G1: Turma | H1: Idade | I1: Renda Familiar | J1: Equipe Example Organization | K1: Agendamento | L1: Status | M1: Motivo | N1: Comentários | O1: Pendências | Q1: Equipe | R1: Observação
A2: =IFERROR(FILTER(Candidatos!A2:J1001,Candidatos!J2:J1001="Team B"),"") | O2: {=BYROW(HSTACK(B2:B1001,J2:L1001),LAMBDA(r,IF(INDEX(r,1,1)="","",TEXTJOIN(" | ",TRUE,IF(INDEX(r,1,2)="","Sem equipe",""),IF(INDEX(r,1,3)="","Sem agendamento",""),IF(INDEX(r,1,4)="","Sem status","")))))} | Q2: Team B | R2: Dados cadastrais automáticos. Edite Agendamento, Status, Motivo e Comentários nas colunas K:N.
Q3: Total | R3: =COUNTIFS(Candidatos!B2:B1001,"?*",Candidatos!J2:J1001,"Team B")

Sheet Team C
A1: ID | B1: Nome do inscrito(a) | C1: Data de inscrição | D1: E-mail | E1: Contato | F1: Região | G1: Turma | H1: Idade | I1: Renda Familiar | J1: Equipe Example Organization | K1: Agendamento | L1: Status | M1: Motivo | N1: Comentários | O1: Pendências | Q1: Equipe | R1: Observação
A2: =IFERROR(FILTER(Candidatos!A2:J1001,Candidatos!J2:J1001="Team C"),"") | O2: {=BYROW(HSTACK(B2:B1001,J2:L1001),LAMBDA(r,IF(INDEX(r,1,1)="","",TEXTJOIN(" | ",TRUE,IF(INDEX(r,1,2)="","Sem equipe",""),IF(INDEX(r,1,3)="","Sem agendamento",""),IF(INDEX(r,1,4)="","Sem status","")))))} | Q2: Team C | R2: Dados cadastrais automáticos. Edite Agendamento, Status, Motivo e Comentários nas colunas K:N.
Q3: Total | R3: =COUNTIFS(Candidatos!B2:B1001,"?*",Candidatos!J2:J1001,"Team C")
